[2023-10-02T01:48:42.321+0000] {taskinstance.py:1103} INFO - Dependencies all met for dep_context=non-requeueable deps ti=<TaskInstance: Load-Green-Taxi-Data-Web-To-GCS-To-Postgres.download_file_from_gcs scheduled__2019-09-02T06:00:00+00:00 [queued]>
[2023-10-02T01:48:42.332+0000] {taskinstance.py:1103} INFO - Dependencies all met for dep_context=requeueable deps ti=<TaskInstance: Load-Green-Taxi-Data-Web-To-GCS-To-Postgres.download_file_from_gcs scheduled__2019-09-02T06:00:00+00:00 [queued]>
[2023-10-02T01:48:42.333+0000] {taskinstance.py:1308} INFO - Starting attempt 3 of 3
[2023-10-02T01:48:42.368+0000] {taskinstance.py:1327} INFO - Executing <Task(GCSToLocalFilesystemOperator): download_file_from_gcs> on 2019-09-02 06:00:00+00:00
[2023-10-02T01:48:42.376+0000] {standard_task_runner.py:57} INFO - Started process 2165 to run task
[2023-10-02T01:48:42.380+0000] {standard_task_runner.py:84} INFO - Running: ['***', 'tasks', 'run', 'Load-Green-Taxi-Data-Web-To-GCS-To-Postgres', 'download_file_from_gcs', 'scheduled__2019-09-02T06:00:00+00:00', '--job-id', '683', '--raw', '--subdir', 'DAGS_FOLDER/web_gcs_pg.py', '--cfg-path', '/tmp/tmp83240zhx']
[2023-10-02T01:48:42.383+0000] {standard_task_runner.py:85} INFO - Job 683: Subtask download_file_from_gcs
[2023-10-02T01:48:42.443+0000] {task_command.py:410} INFO - Running <TaskInstance: Load-Green-Taxi-Data-Web-To-GCS-To-Postgres.download_file_from_gcs scheduled__2019-09-02T06:00:00+00:00 [running]> on host 537710aea1a2
[2023-10-02T01:48:42.626+0000] {taskinstance.py:1547} INFO - Exporting env vars: AIRFLOW_CTX_DAG_EMAIL='' AIRFLOW_CTX_DAG_OWNER='***' AIRFLOW_CTX_DAG_ID='Load-Green-Taxi-Data-Web-To-GCS-To-Postgres' AIRFLOW_CTX_TASK_ID='download_file_from_gcs' AIRFLOW_CTX_EXECUTION_DATE='2019-09-02T06:00:00+00:00' AIRFLOW_CTX_TRY_NUMBER='3' AIRFLOW_CTX_DAG_RUN_ID='scheduled__2019-09-02T06:00:00+00:00'
[2023-10-02T01:48:42.627+0000] {gcs_to_local.py:111} INFO - Executing download: practice18, green/green_tripdata_2019-09.csv, /tmp/tmp1pveeb3i/green_tripdata_2019-09.csv
[2023-10-02T01:48:42.628+0000] {crypto.py:83} WARNING - empty cryptography key - values will not be stored encrypted.
[2023-10-02T01:48:42.629+0000] {base.py:73} INFO - Using connection ID 'google_cloud_default' for task execution.
[2023-10-02T01:48:42.676+0000] {taskinstance.py:1824} ERROR - Task failed with exception
Traceback (most recent call last):
  File "/home/airflow/.local/lib/python3.7/site-packages/airflow/providers/google/cloud/transfers/gcs_to_local.py", line 125, in execute
    hook.download(bucket_name=self.bucket, object_name=self.object_name, filename=self.filename)
  File "/home/airflow/.local/lib/python3.7/site-packages/airflow/providers/google/cloud/hooks/gcs.py", line 340, in download
    blob.download_to_filename(filename, timeout=timeout)
  File "/home/airflow/.local/lib/python3.7/site-packages/google/cloud/storage/blob.py", line 1255, in download_to_filename
    with open(filename, "wb") as file_obj:
FileNotFoundError: [Errno 2] No such file or directory: '/tmp/tmp1pveeb3i/green_tripdata_2019-09.csv'
[2023-10-02T01:48:42.699+0000] {taskinstance.py:1350} INFO - Marking task as FAILED. dag_id=Load-Green-Taxi-Data-Web-To-GCS-To-Postgres, task_id=download_file_from_gcs, execution_date=20190902T060000, start_date=20231002T014842, end_date=20231002T014842
[2023-10-02T01:48:42.734+0000] {warnings.py:110} WARNING - /home/***/.local/lib/python3.7/site-packages/***/utils/email.py:153: RemovedInAirflow3Warning: Fetching SMTP credentials from configuration variables will be deprecated in a future release. Please set credentials using a connection instead.
  send_mime_email(e_from=mail_from, e_to=recipients, mime_msg=msg, conn_id=conn_id, dryrun=dryrun)

[2023-10-02T01:48:42.735+0000] {configuration.py:673} WARNING - section/key [smtp/smtp_user] not found in config
[2023-10-02T01:48:42.735+0000] {email.py:269} INFO - Email alerting: attempt 1
[2023-10-02T01:48:42.746+0000] {configuration.py:673} WARNING - section/key [smtp/smtp_user] not found in config
[2023-10-02T01:48:42.747+0000] {email.py:269} INFO - Email alerting: attempt 1
[2023-10-02T01:48:42.747+0000] {taskinstance.py:1889} ERROR - Failed to send email to: ['']
Traceback (most recent call last):
  File "/home/airflow/.local/lib/python3.7/site-packages/airflow/models/taskinstance.py", line 1407, in _run_raw_task
    self._execute_task_with_callbacks(context, test_mode)
  File "/home/airflow/.local/lib/python3.7/site-packages/airflow/models/taskinstance.py", line 1558, in _execute_task_with_callbacks
    result = self._execute_task(context, task_orig)
  File "/home/airflow/.local/lib/python3.7/site-packages/airflow/models/taskinstance.py", line 1628, in _execute_task
    result = execute_callable(context=context)
  File "/home/airflow/.local/lib/python3.7/site-packages/airflow/providers/google/cloud/transfers/gcs_to_local.py", line 125, in execute
    hook.download(bucket_name=self.bucket, object_name=self.object_name, filename=self.filename)
  File "/home/airflow/.local/lib/python3.7/site-packages/airflow/providers/google/cloud/hooks/gcs.py", line 340, in download
    blob.download_to_filename(filename, timeout=timeout)
  File "/home/airflow/.local/lib/python3.7/site-packages/google/cloud/storage/blob.py", line 1255, in download_to_filename
    with open(filename, "wb") as file_obj:
FileNotFoundError: [Errno 2] No such file or directory: '/tmp/tmp1pveeb3i/green_tripdata_2019-09.csv'

During handling of the above exception, another exception occurred:

Traceback (most recent call last):
  File "/home/airflow/.local/lib/python3.7/site-packages/airflow/models/taskinstance.py", line 2295, in email_alert
    send_email(task.email, subject, html_content)
  File "/home/airflow/.local/lib/python3.7/site-packages/airflow/utils/email.py", line 92, in send_email
    **kwargs,
  File "/home/airflow/.local/lib/python3.7/site-packages/airflow/utils/email.py", line 153, in send_email_smtp
    send_mime_email(e_from=mail_from, e_to=recipients, mime_msg=msg, conn_id=conn_id, dryrun=dryrun)
  File "/home/airflow/.local/lib/python3.7/site-packages/airflow/utils/email.py", line 271, in send_mime_email
    smtp_conn = _get_smtp_connection(smtp_host, smtp_port, smtp_timeout, smtp_ssl)
  File "/home/airflow/.local/lib/python3.7/site-packages/airflow/utils/email.py", line 318, in _get_smtp_connection
    else smtplib.SMTP(host=host, port=port, timeout=timeout)
  File "/usr/local/lib/python3.7/smtplib.py", line 251, in __init__
    (code, msg) = self.connect(host, port)
  File "/usr/local/lib/python3.7/smtplib.py", line 336, in connect
    self.sock = self._get_socket(host, port, self.timeout)
  File "/usr/local/lib/python3.7/smtplib.py", line 307, in _get_socket
    self.source_address)
  File "/usr/local/lib/python3.7/socket.py", line 728, in create_connection
    raise err
  File "/usr/local/lib/python3.7/socket.py", line 716, in create_connection
    sock.connect(sa)
OSError: [Errno 99] Cannot assign requested address

During handling of the above exception, another exception occurred:

Traceback (most recent call last):
  File "/home/airflow/.local/lib/python3.7/site-packages/airflow/models/taskinstance.py", line 1887, in handle_failure
    self.email_alert(error, task)
  File "/home/airflow/.local/lib/python3.7/site-packages/airflow/models/taskinstance.py", line 2297, in email_alert
    send_email(task.email, subject, html_content_err)
  File "/home/airflow/.local/lib/python3.7/site-packages/airflow/utils/email.py", line 92, in send_email
    **kwargs,
  File "/home/airflow/.local/lib/python3.7/site-packages/airflow/utils/email.py", line 153, in send_email_smtp
    send_mime_email(e_from=mail_from, e_to=recipients, mime_msg=msg, conn_id=conn_id, dryrun=dryrun)
  File "/home/airflow/.local/lib/python3.7/site-packages/airflow/utils/email.py", line 271, in send_mime_email
    smtp_conn = _get_smtp_connection(smtp_host, smtp_port, smtp_timeout, smtp_ssl)
  File "/home/airflow/.local/lib/python3.7/site-packages/airflow/utils/email.py", line 318, in _get_smtp_connection
    else smtplib.SMTP(host=host, port=port, timeout=timeout)
  File "/usr/local/lib/python3.7/smtplib.py", line 251, in __init__
    (code, msg) = self.connect(host, port)
  File "/usr/local/lib/python3.7/smtplib.py", line 336, in connect
    self.sock = self._get_socket(host, port, self.timeout)
  File "/usr/local/lib/python3.7/smtplib.py", line 307, in _get_socket
    self.source_address)
  File "/usr/local/lib/python3.7/socket.py", line 728, in create_connection
    raise err
  File "/usr/local/lib/python3.7/socket.py", line 716, in create_connection
    sock.connect(sa)
OSError: [Errno 99] Cannot assign requested address
[2023-10-02T01:48:42.805+0000] {standard_task_runner.py:109} ERROR - Failed to execute job 683 for task download_file_from_gcs ([Errno 2] No such file or directory: '/tmp/tmp1pveeb3i/green_tripdata_2019-09.csv'; 2165)
[2023-10-02T01:48:42.836+0000] {local_task_job_runner.py:225} INFO - Task exited with return code 1
[2023-10-02T01:48:42.870+0000] {taskinstance.py:2653} INFO - 0 downstream tasks scheduled from follow-on schedule check
