[2023-10-02T18:40:02.526+0000] {taskinstance.py:1103} INFO - Dependencies all met for dep_context=non-requeueable deps ti=<TaskInstance: Load-Green-Taxi-Data-Web-To-GCS-To-Postgres.extract_from_web_to_gcs scheduled__2019-07-02T06:00:00+00:00 [queued]>
[2023-10-02T18:40:03.870+0000] {taskinstance.py:1103} INFO - Dependencies all met for dep_context=requeueable deps ti=<TaskInstance: Load-Green-Taxi-Data-Web-To-GCS-To-Postgres.extract_from_web_to_gcs scheduled__2019-07-02T06:00:00+00:00 [queued]>
[2023-10-02T18:40:03.871+0000] {taskinstance.py:1308} INFO - Starting attempt 1 of 3
[2023-10-02T18:40:04.807+0000] {taskinstance.py:1327} INFO - Executing <Task(WebToGCSHKOperator): extract_from_web_to_gcs> on 2019-07-02 06:00:00+00:00
[2023-10-02T18:40:04.827+0000] {standard_task_runner.py:57} INFO - Started process 9257 to run task
[2023-10-02T18:40:04.833+0000] {standard_task_runner.py:84} INFO - Running: ['***', 'tasks', 'run', 'Load-Green-Taxi-Data-Web-To-GCS-To-Postgres', 'extract_from_web_to_gcs', 'scheduled__2019-07-02T06:00:00+00:00', '--job-id', '1020', '--raw', '--subdir', 'DAGS_FOLDER/web_gcs_pg.py', '--cfg-path', '/tmp/tmp50wp0sae']
[2023-10-02T18:40:04.837+0000] {standard_task_runner.py:85} INFO - Job 1020: Subtask extract_from_web_to_gcs
[2023-10-02T18:40:07.781+0000] {task_command.py:410} INFO - Running <TaskInstance: Load-Green-Taxi-Data-Web-To-GCS-To-Postgres.extract_from_web_to_gcs scheduled__2019-07-02T06:00:00+00:00 [running]> on host 537710aea1a2
[2023-10-02T18:40:11.394+0000] {taskinstance.py:1547} INFO - Exporting env vars: AIRFLOW_CTX_DAG_EMAIL='' AIRFLOW_CTX_DAG_OWNER='***' AIRFLOW_CTX_DAG_ID='Load-Green-Taxi-Data-Web-To-GCS-To-Postgres' AIRFLOW_CTX_TASK_ID='extract_from_web_to_gcs' AIRFLOW_CTX_EXECUTION_DATE='2019-07-02T06:00:00+00:00' AIRFLOW_CTX_TRY_NUMBER='1' AIRFLOW_CTX_DAG_RUN_ID='scheduled__2019-07-02T06:00:00+00:00'
[2023-10-02T18:40:12.121+0000] {crypto.py:83} WARNING - empty cryptography key - values will not be stored encrypted.
[2023-10-02T18:40:12.122+0000] {base.py:73} INFO - Using connection ID 'google_cloud_default' for task execution.
[2023-10-02T18:40:12.123+0000] {Web_To_GCS_Hook.py:67} INFO - Execute downloading of file from https://github.com/DataTalksClub/nyc-tlc-data/releases/download/green/green_tripdata_2019-07.csv.gz to gs://practice18//green_tripdata_2019-07.csv.gz
[2023-10-02T18:41:04.130+0000] {taskinstance.py:1824} ERROR - Task failed with exception
Traceback (most recent call last):
  File "/home/airflow/.local/lib/python3.7/site-packages/urllib3/connection.py", line 175, in _new_conn
    (self._dns_host, self.port), self.timeout, **extra_kw
  File "/home/airflow/.local/lib/python3.7/site-packages/urllib3/util/connection.py", line 95, in create_connection
    raise err
  File "/home/airflow/.local/lib/python3.7/site-packages/urllib3/util/connection.py", line 85, in create_connection
    sock.connect(sa)
OSError: [Errno 101] Network is unreachable

During handling of the above exception, another exception occurred:

Traceback (most recent call last):
  File "/home/airflow/.local/lib/python3.7/site-packages/urllib3/connectionpool.py", line 721, in urlopen
    chunked=chunked,
  File "/home/airflow/.local/lib/python3.7/site-packages/urllib3/connectionpool.py", line 403, in _make_request
    self._validate_conn(conn)
  File "/home/airflow/.local/lib/python3.7/site-packages/urllib3/connectionpool.py", line 1053, in _validate_conn
    conn.connect()
  File "/home/airflow/.local/lib/python3.7/site-packages/urllib3/connection.py", line 363, in connect
    self.sock = conn = self._new_conn()
  File "/home/airflow/.local/lib/python3.7/site-packages/urllib3/connection.py", line 187, in _new_conn
    self, "Failed to establish a new connection: %s" % e
urllib3.exceptions.NewConnectionError: <urllib3.connection.HTTPSConnection object at 0x7f120a94eb90>: Failed to establish a new connection: [Errno 101] Network is unreachable

During handling of the above exception, another exception occurred:

Traceback (most recent call last):
  File "/home/airflow/.local/lib/python3.7/site-packages/requests/adapters.py", line 497, in send
    chunked=chunked,
  File "/home/airflow/.local/lib/python3.7/site-packages/urllib3/connectionpool.py", line 799, in urlopen
    method, url, error=e, _pool=self, _stacktrace=sys.exc_info()[2]
  File "/home/airflow/.local/lib/python3.7/site-packages/urllib3/util/retry.py", line 592, in increment
    raise MaxRetryError(_pool, url, error or ResponseError(cause))
urllib3.exceptions.MaxRetryError: HTTPSConnectionPool(host='objects.githubusercontent.com', port=443): Max retries exceeded with url: /github-production-release-asset-2e65be/513814948/ff39d7b6-a867-4007-b05e-2b9044d2e1c9?X-Amz-Algorithm=AWS4-HMAC-SHA256&X-Amz-Credential=AKIAIWNJYAX4CSVEH53A%2F20231002%2Fus-east-1%2Fs3%2Faws4_request&X-Amz-Date=20231002T184025Z&X-Amz-Expires=300&X-Amz-Signature=bd20b295b1d6ccb838c3b9efa3a2bd20b9ac07f7e846e9c9b86f73c5bfd0a4ee&X-Amz-SignedHeaders=host&actor_id=0&key_id=0&repo_id=513814948&response-content-disposition=attachment%3B%20filename%3Dgreen_tripdata_2019-07.csv.gz&response-content-type=application%2Foctet-stream (Caused by NewConnectionError('<urllib3.connection.HTTPSConnection object at 0x7f120a94eb90>: Failed to establish a new connection: [Errno 101] Network is unreachable'))

During handling of the above exception, another exception occurred:

Traceback (most recent call last):
  File "/opt/airflow/plugins/web/operators/Web_To_GCS_Hook.py", line 58, in execute
    self._copy_file_object(gcs_hook)
  File "/opt/airflow/plugins/web/operators/Web_To_GCS_Hook.py", line 75, in _copy_file_object
    r = requests.get(request_url)
  File "/home/airflow/.local/lib/python3.7/site-packages/requests/api.py", line 73, in get
    return request("get", url, params=params, **kwargs)
  File "/home/airflow/.local/lib/python3.7/site-packages/requests/api.py", line 59, in request
    return session.request(method=method, url=url, **kwargs)
  File "/home/airflow/.local/lib/python3.7/site-packages/requests/sessions.py", line 589, in request
    resp = self.send(prep, **send_kwargs)
  File "/home/airflow/.local/lib/python3.7/site-packages/requests/sessions.py", line 725, in send
    history = [resp for resp in gen]
  File "/home/airflow/.local/lib/python3.7/site-packages/requests/sessions.py", line 725, in <listcomp>
    history = [resp for resp in gen]
  File "/home/airflow/.local/lib/python3.7/site-packages/requests/sessions.py", line 274, in resolve_redirects
    **adapter_kwargs,
  File "/home/airflow/.local/lib/python3.7/site-packages/requests/sessions.py", line 703, in send
    r = adapter.send(request, **kwargs)
  File "/home/airflow/.local/lib/python3.7/site-packages/requests/adapters.py", line 519, in send
    raise ConnectionError(e, request=request)
requests.exceptions.ConnectionError: HTTPSConnectionPool(host='objects.githubusercontent.com', port=443): Max retries exceeded with url: /github-production-release-asset-2e65be/513814948/ff39d7b6-a867-4007-b05e-2b9044d2e1c9?X-Amz-Algorithm=AWS4-HMAC-SHA256&X-Amz-Credential=AKIAIWNJYAX4CSVEH53A%2F20231002%2Fus-east-1%2Fs3%2Faws4_request&X-Amz-Date=20231002T184025Z&X-Amz-Expires=300&X-Amz-Signature=bd20b295b1d6ccb838c3b9efa3a2bd20b9ac07f7e846e9c9b86f73c5bfd0a4ee&X-Amz-SignedHeaders=host&actor_id=0&key_id=0&repo_id=513814948&response-content-disposition=attachment%3B%20filename%3Dgreen_tripdata_2019-07.csv.gz&response-content-type=application%2Foctet-stream (Caused by NewConnectionError('<urllib3.connection.HTTPSConnection object at 0x7f120a94eb90>: Failed to establish a new connection: [Errno 101] Network is unreachable'))
[2023-10-02T18:41:08.375+0000] {taskinstance.py:1350} INFO - Marking task as UP_FOR_RETRY. dag_id=Load-Green-Taxi-Data-Web-To-GCS-To-Postgres, task_id=extract_from_web_to_gcs, execution_date=20190702T060000, start_date=20231002T184003, end_date=20231002T184108
[2023-10-02T18:41:09.179+0000] {standard_task_runner.py:109} ERROR - Failed to execute job 1020 for task extract_from_web_to_gcs (HTTPSConnectionPool(host='objects.githubusercontent.com', port=443): Max retries exceeded with url: /github-production-release-asset-2e65be/513814948/ff39d7b6-a867-4007-b05e-2b9044d2e1c9?X-Amz-Algorithm=AWS4-HMAC-SHA256&X-Amz-Credential=AKIAIWNJYAX4CSVEH53A%2F20231002%2Fus-east-1%2Fs3%2Faws4_request&X-Amz-Date=20231002T184025Z&X-Amz-Expires=300&X-Amz-Signature=bd20b295b1d6ccb838c3b9efa3a2bd20b9ac07f7e846e9c9b86f73c5bfd0a4ee&X-Amz-SignedHeaders=host&actor_id=0&key_id=0&repo_id=513814948&response-content-disposition=attachment%3B%20filename%3Dgreen_tripdata_2019-07.csv.gz&response-content-type=application%2Foctet-stream (Caused by NewConnectionError('<urllib3.connection.HTTPSConnection object at 0x7f120a94eb90>: Failed to establish a new connection: [Errno 101] Network is unreachable')); 9257)
[2023-10-02T18:41:09.232+0000] {local_task_job_runner.py:225} INFO - Task exited with return code 1
[2023-10-02T18:41:09.258+0000] {taskinstance.py:2653} INFO - 0 downstream tasks scheduled from follow-on schedule check
