[2023-10-02T00:48:39.016+0000] {taskinstance.py:1103} INFO - Dependencies all met for dep_context=non-requeueable deps ti=<TaskInstance: Load-Green-Taxi-Data-Web-To-GCS-To-Postgres.load_to_postgres scheduled__2019-05-02T06:00:00+00:00 [queued]>
[2023-10-02T00:48:39.029+0000] {taskinstance.py:1103} INFO - Dependencies all met for dep_context=requeueable deps ti=<TaskInstance: Load-Green-Taxi-Data-Web-To-GCS-To-Postgres.load_to_postgres scheduled__2019-05-02T06:00:00+00:00 [queued]>
[2023-10-02T00:48:39.029+0000] {taskinstance.py:1308} INFO - Starting attempt 3 of 3
[2023-10-02T00:48:39.068+0000] {taskinstance.py:1327} INFO - Executing <Task(PostgresOperator): load_to_postgres> on 2019-05-02 06:00:00+00:00
[2023-10-02T00:48:39.075+0000] {standard_task_runner.py:57} INFO - Started process 1087 to run task
[2023-10-02T00:48:39.078+0000] {standard_task_runner.py:84} INFO - Running: ['***', 'tasks', 'run', 'Load-Green-Taxi-Data-Web-To-GCS-To-Postgres', 'load_to_postgres', 'scheduled__2019-05-02T06:00:00+00:00', '--job-id', '665', '--raw', '--subdir', 'DAGS_FOLDER/web_gcs_pg.py', '--cfg-path', '/tmp/tmptrwmaa3w']
[2023-10-02T00:48:39.082+0000] {standard_task_runner.py:85} INFO - Job 665: Subtask load_to_postgres
[2023-10-02T00:48:39.144+0000] {task_command.py:410} INFO - Running <TaskInstance: Load-Green-Taxi-Data-Web-To-GCS-To-Postgres.load_to_postgres scheduled__2019-05-02T06:00:00+00:00 [running]> on host 537710aea1a2
[2023-10-02T00:48:39.286+0000] {abstractoperator.py:598} ERROR - Exception rendering Jinja template for task 'load_to_postgres', field 'sql'. Template: "-- create green table\nCREATE TABLE IF NOT EXISTS {{ SERVICE }} (\n       VendorID INT,\n       lpep_pickup_datetime TIMESTAMP,\n       lpep_dropoff_datetime TIMESTAMP,\n       store_and_fwd_flag STRING,\n       RatecodeID FLOAT,\n       PULocationID FLOAT,\n       DOLocationID FLOAT,\n       passenger_count FLOAT,\n       trip_distance FLOAT,\n       fare_amount FLOAT,\n       extra FLOAT,\n       mta_tax FLOAT,\n       tip_amount FLOAT,\n       tolls_amount FLOAT,\n       ehail_fee FLOAT,\n       improvement_surcharge FLOAT,\n       total_amount FLOAT,\n       payment_type FLOAT,\n       trip_type FLOAT,\n       congestion_surcharge FLOAT\n   );\n\n-- ingest data\nCOPY {{ SERVICE }} FROM '{{ PATH_TO_SAVED_FILE }}' CSV HEADER;\n"
Traceback (most recent call last):
  File "/home/airflow/.local/lib/python3.7/site-packages/airflow/models/abstractoperator.py", line 590, in _do_render_template_fields
    seen_oids,
  File "/home/airflow/.local/lib/python3.7/site-packages/airflow/template/templater.py", line 156, in render_template
    return self._render(template, context)
  File "/home/airflow/.local/lib/python3.7/site-packages/airflow/models/abstractoperator.py", line 540, in _render
    return super()._render(template, context, dag=dag)
  File "/home/airflow/.local/lib/python3.7/site-packages/airflow/template/templater.py", line 113, in _render
    return render_template_to_string(template, context)
  File "/home/airflow/.local/lib/python3.7/site-packages/airflow/utils/helpers.py", line 288, in render_template_to_string
    return render_template(template, cast(MutableMapping[str, Any], context), native=False)
  File "/home/airflow/.local/lib/python3.7/site-packages/airflow/utils/helpers.py", line 283, in render_template
    return "".join(nodes)
  File "<template>", line 14, in root
  File "/home/airflow/.local/lib/python3.7/site-packages/jinja2/runtime.py", line 852, in _fail_with_undefined_error
    raise self._undefined_exception(self._undefined_message)
jinja2.exceptions.UndefinedError: 'SERVICE' is undefined
[2023-10-02T00:48:39.288+0000] {taskinstance.py:1824} ERROR - Task failed with exception
Traceback (most recent call last):
  File "/home/airflow/.local/lib/python3.7/site-packages/airflow/models/taskinstance.py", line 1407, in _run_raw_task
    self._execute_task_with_callbacks(context, test_mode)
  File "/home/airflow/.local/lib/python3.7/site-packages/airflow/models/taskinstance.py", line 1531, in _execute_task_with_callbacks
    task_orig = self.render_templates(context=context)
  File "/home/airflow/.local/lib/python3.7/site-packages/airflow/models/taskinstance.py", line 2179, in render_templates
    original_task.render_template_fields(context)
  File "/home/airflow/.local/lib/python3.7/site-packages/airflow/models/baseoperator.py", line 1254, in render_template_fields
    self._do_render_template_fields(self, self.template_fields, context, jinja_env, set())
  File "/home/airflow/.local/lib/python3.7/site-packages/airflow/utils/session.py", line 76, in wrapper
    return func(*args, session=session, **kwargs)
  File "/home/airflow/.local/lib/python3.7/site-packages/airflow/models/abstractoperator.py", line 590, in _do_render_template_fields
    seen_oids,
  File "/home/airflow/.local/lib/python3.7/site-packages/airflow/template/templater.py", line 156, in render_template
    return self._render(template, context)
  File "/home/airflow/.local/lib/python3.7/site-packages/airflow/models/abstractoperator.py", line 540, in _render
    return super()._render(template, context, dag=dag)
  File "/home/airflow/.local/lib/python3.7/site-packages/airflow/template/templater.py", line 113, in _render
    return render_template_to_string(template, context)
  File "/home/airflow/.local/lib/python3.7/site-packages/airflow/utils/helpers.py", line 288, in render_template_to_string
    return render_template(template, cast(MutableMapping[str, Any], context), native=False)
  File "/home/airflow/.local/lib/python3.7/site-packages/airflow/utils/helpers.py", line 283, in render_template
    return "".join(nodes)
  File "<template>", line 14, in root
  File "/home/airflow/.local/lib/python3.7/site-packages/jinja2/runtime.py", line 852, in _fail_with_undefined_error
    raise self._undefined_exception(self._undefined_message)
jinja2.exceptions.UndefinedError: 'SERVICE' is undefined
[2023-10-02T00:48:39.300+0000] {taskinstance.py:1350} INFO - Marking task as FAILED. dag_id=Load-Green-Taxi-Data-Web-To-GCS-To-Postgres, task_id=load_to_postgres, execution_date=20190502T060000, start_date=20231002T004839, end_date=20231002T004839
[2023-10-02T00:48:39.328+0000] {warnings.py:110} WARNING - /home/***/.local/lib/python3.7/site-packages/***/utils/email.py:153: RemovedInAirflow3Warning: Fetching SMTP credentials from configuration variables will be deprecated in a future release. Please set credentials using a connection instead.
  send_mime_email(e_from=mail_from, e_to=recipients, mime_msg=msg, conn_id=conn_id, dryrun=dryrun)

[2023-10-02T00:48:39.329+0000] {configuration.py:673} WARNING - section/key [smtp/smtp_user] not found in config
[2023-10-02T00:48:39.329+0000] {email.py:269} INFO - Email alerting: attempt 1
[2023-10-02T00:48:39.340+0000] {configuration.py:673} WARNING - section/key [smtp/smtp_user] not found in config
[2023-10-02T00:48:39.341+0000] {email.py:269} INFO - Email alerting: attempt 1
[2023-10-02T00:48:39.341+0000] {taskinstance.py:1889} ERROR - Failed to send email to: ['']
Traceback (most recent call last):
  File "/home/airflow/.local/lib/python3.7/site-packages/airflow/models/taskinstance.py", line 1407, in _run_raw_task
    self._execute_task_with_callbacks(context, test_mode)
  File "/home/airflow/.local/lib/python3.7/site-packages/airflow/models/taskinstance.py", line 1531, in _execute_task_with_callbacks
    task_orig = self.render_templates(context=context)
  File "/home/airflow/.local/lib/python3.7/site-packages/airflow/models/taskinstance.py", line 2179, in render_templates
    original_task.render_template_fields(context)
  File "/home/airflow/.local/lib/python3.7/site-packages/airflow/models/baseoperator.py", line 1254, in render_template_fields
    self._do_render_template_fields(self, self.template_fields, context, jinja_env, set())
  File "/home/airflow/.local/lib/python3.7/site-packages/airflow/utils/session.py", line 76, in wrapper
    return func(*args, session=session, **kwargs)
  File "/home/airflow/.local/lib/python3.7/site-packages/airflow/models/abstractoperator.py", line 590, in _do_render_template_fields
    seen_oids,
  File "/home/airflow/.local/lib/python3.7/site-packages/airflow/template/templater.py", line 156, in render_template
    return self._render(template, context)
  File "/home/airflow/.local/lib/python3.7/site-packages/airflow/models/abstractoperator.py", line 540, in _render
    return super()._render(template, context, dag=dag)
  File "/home/airflow/.local/lib/python3.7/site-packages/airflow/template/templater.py", line 113, in _render
    return render_template_to_string(template, context)
  File "/home/airflow/.local/lib/python3.7/site-packages/airflow/utils/helpers.py", line 288, in render_template_to_string
    return render_template(template, cast(MutableMapping[str, Any], context), native=False)
  File "/home/airflow/.local/lib/python3.7/site-packages/airflow/utils/helpers.py", line 283, in render_template
    return "".join(nodes)
  File "<template>", line 14, in root
  File "/home/airflow/.local/lib/python3.7/site-packages/jinja2/runtime.py", line 852, in _fail_with_undefined_error
    raise self._undefined_exception(self._undefined_message)
jinja2.exceptions.UndefinedError: 'SERVICE' is undefined

During handling of the above exception, another exception occurred:

Traceback (most recent call last):
  File "/home/airflow/.local/lib/python3.7/site-packages/airflow/models/taskinstance.py", line 2295, in email_alert
    send_email(task.email, subject, html_content)
  File "/home/airflow/.local/lib/python3.7/site-packages/airflow/utils/email.py", line 92, in send_email
    **kwargs,
  File "/home/airflow/.local/lib/python3.7/site-packages/airflow/utils/email.py", line 153, in send_email_smtp
    send_mime_email(e_from=mail_from, e_to=recipients, mime_msg=msg, conn_id=conn_id, dryrun=dryrun)
  File "/home/airflow/.local/lib/python3.7/site-packages/airflow/utils/email.py", line 271, in send_mime_email
    smtp_conn = _get_smtp_connection(smtp_host, smtp_port, smtp_timeout, smtp_ssl)
  File "/home/airflow/.local/lib/python3.7/site-packages/airflow/utils/email.py", line 318, in _get_smtp_connection
    else smtplib.SMTP(host=host, port=port, timeout=timeout)
  File "/usr/local/lib/python3.7/smtplib.py", line 251, in __init__
    (code, msg) = self.connect(host, port)
  File "/usr/local/lib/python3.7/smtplib.py", line 336, in connect
    self.sock = self._get_socket(host, port, self.timeout)
  File "/usr/local/lib/python3.7/smtplib.py", line 307, in _get_socket
    self.source_address)
  File "/usr/local/lib/python3.7/socket.py", line 728, in create_connection
    raise err
  File "/usr/local/lib/python3.7/socket.py", line 716, in create_connection
    sock.connect(sa)
OSError: [Errno 99] Cannot assign requested address

During handling of the above exception, another exception occurred:

Traceback (most recent call last):
  File "/home/airflow/.local/lib/python3.7/site-packages/airflow/models/taskinstance.py", line 1887, in handle_failure
    self.email_alert(error, task)
  File "/home/airflow/.local/lib/python3.7/site-packages/airflow/models/taskinstance.py", line 2297, in email_alert
    send_email(task.email, subject, html_content_err)
  File "/home/airflow/.local/lib/python3.7/site-packages/airflow/utils/email.py", line 92, in send_email
    **kwargs,
  File "/home/airflow/.local/lib/python3.7/site-packages/airflow/utils/email.py", line 153, in send_email_smtp
    send_mime_email(e_from=mail_from, e_to=recipients, mime_msg=msg, conn_id=conn_id, dryrun=dryrun)
  File "/home/airflow/.local/lib/python3.7/site-packages/airflow/utils/email.py", line 271, in send_mime_email
    smtp_conn = _get_smtp_connection(smtp_host, smtp_port, smtp_timeout, smtp_ssl)
  File "/home/airflow/.local/lib/python3.7/site-packages/airflow/utils/email.py", line 318, in _get_smtp_connection
    else smtplib.SMTP(host=host, port=port, timeout=timeout)
  File "/usr/local/lib/python3.7/smtplib.py", line 251, in __init__
    (code, msg) = self.connect(host, port)
  File "/usr/local/lib/python3.7/smtplib.py", line 336, in connect
    self.sock = self._get_socket(host, port, self.timeout)
  File "/usr/local/lib/python3.7/smtplib.py", line 307, in _get_socket
    self.source_address)
  File "/usr/local/lib/python3.7/socket.py", line 728, in create_connection
    raise err
  File "/usr/local/lib/python3.7/socket.py", line 716, in create_connection
    sock.connect(sa)
OSError: [Errno 99] Cannot assign requested address
[2023-10-02T00:48:39.367+0000] {standard_task_runner.py:109} ERROR - Failed to execute job 665 for task load_to_postgres ('SERVICE' is undefined; 1087)
[2023-10-02T00:48:39.411+0000] {local_task_job_runner.py:225} INFO - Task exited with return code 1
[2023-10-02T00:48:39.440+0000] {taskinstance.py:2653} INFO - 0 downstream tasks scheduled from follow-on schedule check
